<?xml version="1.0"?>
<!-- This URDF was automatically created by SolidWorks to URDF Exporter! -->
<robot xmlns:xacro="http://www.ros.org/wiki/xacro">
    <xacro:macro name="left_xacro" params="">
        <link
            name="left_link">
            <inertial>
            <origin
                xyz="-1.74331101290837E-07 -0.00020820313081131 3.92074334179537E-08"
                rpy="0 0 0" />
            <mass
                value="0.0456749739710292" />
            <inertia
                ixx="1.81808804758144E-05"
                ixy="-1.75758106169756E-11"
                ixz="3.9951170980621E-12"
                iyy="3.14403862750805E-05"
                iyz="1.23310532276976E-11"
                izz="1.81803658343481E-05" />
            </inertial>
            <visual>
            <origin
                xyz="0 0 0"
                rpy="0 0 0" />
            <geometry>
                <mesh
                filename="package://fishbot_description/meshes/left_link.STL" />
            </geometry>
            <material
                name="">
                <color
                rgba="0.3 0.3 0.3 1" />
            </material>
            </visual>

            <collision>
            <origin
                xyz="0 0 0"
                rpy="0 0 0" />
            <geometry>
                <mesh
                filename="package://fishbot_description/meshes/left_link.STL" />
            </geometry>
            </collision>
        </link>

  
        <gazebo reference="left_link">
            <implicit_spring_damper>1</implicit_spring_damper>
        </gazebo>

        <joint
            name="left_joint"
            type="continuous">
            <origin
            xyz="-0.069657 0.07975 0.0162"
            rpy="0 0 0" />
            <dynamics 
            damping="0.8"
            friction="0.3"/>
            <parent
            link="base_link" />
            <child
            link="left_link" />
            <axis
            xyz="0 1 0" />
        </joint>
    </xacro:macro>
</robot>